<sdf version='1.7'>
  <model name='autobot'>
    <link name='base_footprint'>
      <inertial>
        <pose>0.031047 0.004898 -0.030768 0 -0 0</pose>
        <mass>0.9124</mass>
        <inertia>
          <ixx>0.00413591</ixx>
          <ixy>3.10976e-05</ixy>
          <ixz>0.00141599</ixz>
          <iyy>0.00445613</iyy>
          <iyz>1.28042e-05</iyz>
          <izz>0.00556676</izz>
        </inertia>
      </inertial>
      <collision name='base_footprint_fixed_joint_lump__base_link_collision'>
        <pose>0 0 0 0 -0 0</pose>
        <geometry>
          <mesh>
            <scale>1 1 1</scale>
            <uri>model://autobot/meshes/base_link.STL</uri>
          </mesh>
        </geometry>
      </collision>
      <collision name='base_footprint_fixed_joint_lump__castor_wheels_collision_1'>
        <pose>0.17607 0.003608 -0.079343 0 -0 0</pose>
        <geometry>
          <mesh>
            <scale>1 1 1</scale>
            <uri>model://autobot/meshes/castor_wheels.STL</uri>
          </mesh>
        </geometry>
      </collision>
      <collision name='base_footprint_fixed_joint_lump__lidar_collision_2'>
        <pose>0.063868 0.006608 0.070657 0 0 0</pose>
        <geometry>
          <mesh>
            <scale>1 1 1</scale>
            <uri>model://autobot/meshes/lidar.STL</uri>
          </mesh>
        </geometry>
      </collision>
      <visual name='base_footprint_fixed_joint_lump__base_link_visual'>
        <pose>0 0 0 0 -0 0</pose>
        <geometry>
          <mesh>
            <scale>1 1 1</scale>
            <uri>model://autobot/meshes/base_link.STL</uri>
          </mesh>
        </geometry>
      </visual>
      <visual name='base_footprint_fixed_joint_lump__castor_wheels_visual_1'>
        <pose>0.17607 0.003608 -0.079343 0 -0 0</pose>
        <geometry>
          <mesh>
            <scale>1 1 1</scale>
            <uri>model://autobot/meshes/castor_wheels.STL</uri>
          </mesh>
        </geometry>
      </visual>
      <visual name='base_footprint_fixed_joint_lump__lidar_visual_2'>
        <pose>0.063868 0.006608 0.050657 0 0 0</pose>
        <geometry>
          <mesh>
            <scale>1 1 1</scale>
            <uri>model://autobot/meshes/lidar.STL</uri>
          </mesh>
        </geometry>
      </visual>

      <sensor name="lidar_sensor" type="ray">
        <always_on>true</always_on>
        <visualize>true</visualize>
        <pose>0.03 0 0.05 0 0 0</pose> <!-- Adjust the position based on your robot's configuration -->
        <update_rate>30</update_rate>
        <ray>
          <scan>
            <horizontal>
              <samples>360</samples>
              <resolution>1.000000</resolution>
              <min_angle>-1.57</min_angle>
              <max_angle>1.57</max_angle>
            </horizontal>
          </scan>
          <range>
            <min>0.140000</min>
            <max>12.0</max>
            <resolution>0.015000</resolution>
          </range>
          <noise>
            <type>gaussian</type>
            <mean>0.0</mean>
            <stddev>0.01</stddev>
          </noise>
        </ray>
        <plugin name="autobot_laserscan" filename="libgazebo_ros_ray_sensor.so">
          <ros>
            <remapping>~/out:=scan</remapping>
          </ros>
          <output_type>sensor_msgs/LaserScan</output_type>
          <frame_name>lidar</frame_name>
        </plugin>
      </sensor>

    </link>



    <joint name='left_wheel_joint' type='revolute'>
      <pose relative_to='base_footprint'>-0.015294 0.18886 -0.079763 -1.57 0 0</pose>
      <parent>base_footprint</parent>
      <child>left_wheel</child>
      <axis>
        <xyz>0 0 1</xyz>
        <limit>
          <lower>-1e+16</lower>
          <upper>1e+16</upper>
        </limit>
        <dynamics>
          <spring_reference>0</spring_reference>
          <spring_stiffness>0</spring_stiffness>
        </dynamics>
      </axis>
    </joint>
    <link name='left_wheel'>
      <pose relative_to='left_wheel_joint'>0 0 0 0 -0 0</pose>
      <inertial>
        <pose>-2e-06 -0.0035 -8.1e-05 1.57 -0 0</pose>
        <mass>0.10364</mass>
        <inertia>
          <ixx>8.7625e-05</ixx>
          <ixy>1.3327e-18</ixy>
          <ixz>2.4026e-21</ixz>
          <iyy>0.00016817</iyy>
          <iyz>-2.6053e-19</iyz>
          <izz>8.7625e-05</izz>
        </inertia>
      </inertial>
      <collision name='left_wheel_collision'>
        <pose>0 0 0 1.57 -0 0</pose>
        <geometry>
          <mesh>
            <scale>1 1 1</scale>
            <uri>model://autobot/meshes/left_wheel.STL</uri>
          </mesh>
        </geometry>
      </collision>
      <visual name='left_wheel_visual'>
        <pose>0 0 0 1.57 -0 0</pose>
        <geometry>
          <mesh>
            <scale>1 1 1</scale>
            <uri>model://autobot/meshes/left_wheel.STL</uri>
          </mesh>
        </geometry>
      </visual>
    </link>

    <joint name='right_wheel_joint' type='revolute'>
      <pose relative_to='base_footprint'>-0.016418 -0.18164 -0.079762 1.57 -0 0</pose>
      <parent>base_footprint</parent>
      <child>right_wheel</child>
      <axis>
        <xyz>0 0 -1</xyz>
        <limit>
          <lower>-1e+16</lower>
          <upper>1e+16</upper>
        </limit>
        <dynamics>
          <spring_reference>0</spring_reference>
          <spring_stiffness>0</spring_stiffness>
        </dynamics>
      </axis>
    </joint>
    <link name='right_wheel'>
      <pose relative_to='right_wheel_joint'>0 0 0 0 -0 0</pose>
      <inertial>
        <pose>-0 0.0035 -8.1e-05 1.57 -0 0</pose>
        <mass>0.10364</mass>
        <inertia>
          <ixx>8.7625e-05</ixx>
          <ixy>1.349e-18</ixy>
          <ixz>-1.8576e-20</ixz>
          <iyy>0.00016817</iyy>
          <iyz>-3.0937e-19</iyz>
          <izz>8.7625e-05</izz>
        </inertia>
      </inertial>
      <collision name='right_wheel_collision'>
        <pose>0 0 0 1.57 -0 0</pose>
        <geometry>
          <mesh>
            <scale>1 1 1</scale>
            <uri>model://autobot/meshes/right_wheel.STL</uri>
          </mesh>
        </geometry>
      </collision>
      <visual name='right_wheel_visual'>
        <pose>0 0 0 1.57 -0 0</pose>
        <geometry>
          <mesh>
            <scale>1 1 1</scale>
            <uri>model://autobot/meshes/right_wheel.STL</uri>
          </mesh>
        </geometry>
      </visual>
    </link>

    <plugin name="autobot_diff_drive" filename="libgazebo_ros_diff_drive.so">

        <ros>
          <!-- <namespace>/tb3</namespace> -->
          <!--since gazebo_plugins publish tf topic in global namespace /tf only and it
            cannot be remapped like (namespace/tf) through launch arguments -->
          <remapping>/tf:=tf</remapping>
        </ros>

        <update_rate>30</update_rate>

        <!-- wheels -->
        <left_joint>left_wheel_joint</left_joint>
        <right_joint>right_wheel_joint</right_joint>

        <!-- kinematics -->
        <wheel_separation>0.367</wheel_separation>
        <wheel_diameter>0.05</wheel_diameter>

        <!-- limits -->
        <max_wheel_torque>20</max_wheel_torque>
        <max_wheel_acceleration>1.0</max_wheel_acceleration>

        <command_topic>cmd_vel</command_topic>

        <!-- output -->
        <publish_odom>true</publish_odom>
        <publish_odom_tf>true</publish_odom_tf>
        <publish_wheel_tf>false</publish_wheel_tf>

        <odometry_topic>odom</odometry_topic>
        <odometry_frame>odom</odometry_frame>
        <robot_base_frame>base_footprint</robot_base_frame>

    </plugin>

    <plugin name="autobot_joint_state" filename="libgazebo_ros_joint_state_publisher.so">
        <ros>
          <!-- <namespace>/tb3</namespace> -->
            <remapping>~/out:=joint_states</remapping>
        </ros>
        <update_rate>30</update_rate>
        <joint_name>left_wheel_joint</joint_name>
        <joint_name>right_wheel_joint</joint_name>
        <!-- <joint_name>castor_wheels</joint_name> -->
    </plugin>

  </model>
</sdf>
