<?xml version="1.0" ?>
<robot name="autobot" xmlns:xacro="http://ros.org/wiki/xacro">

  <!-- Init colour -->
  <material name="black">
      <color rgba="0.0 0.0 0.0 1.0"/>
  </material>

  <material name="dark">
    <color rgba="0.3 0.3 0.3 1.0"/>
  </material>

  <material name="light_black">
    <color rgba="0.4 0.4 0.4 1.0"/>
  </material>

  <material name="blue">
    <color rgba="0.0 0.0 0.8 1.0"/>
  </material>

  <material name="green">
    <color rgba="0.0 0.8 0.0 1.0"/>
  </material>

  <material name="grey">
    <color rgba="0.5 0.5 0.5 1.0"/>
  </material>

  <material name="orange">
    <color rgba="1.0 0.4235 0.0392 1.0"/>
  </material>

  <material name="brown">
    <color rgba="0.8706 0.8118 0.7647 1.0"/>
  </material>

  <material name="red">
    <color rgba="0.8 0.0 0.0 1.0"/>
  </material>

  <material name="white">
    <color rgba="1.0 1.0 1.0 1.0"/>
  </material>

  <link name="base_footprint"/>

  <joint name="base_footprint_joint" type="fixed">
    <parent link="base_footprint"/>
    <child link="base_link"/>
    <origin xyz="0 0 0" rpy="0 0 0"/>
  </joint>

  <link name="base_link">
    <visual>
      <origin xyz="0 0 0" rpy="0 0 0"/>
      <geometry>
        <mesh filename="package://autobot/meshes/base_link.STL"/>
      </geometry>
      <material name="light_black"/> <!-- Changed to a defined material -->
    </visual>

    <collision>
      <origin xyz="0 0 0" rpy="0 0 0"/>
      <geometry>
        <mesh filename="package://autobot/meshes/base_link.STL"/>
      </geometry>
    </collision>

    <inertial>
      <origin xyz="0.012692 0.0050409 -0.025738" rpy="-0.05 1 -0.05"/>
      <mass value="0.8044"/>
      <inertia ixx="0.0026664" ixy="1.82E-05" ixz="2.9353E-07" iyy="0.0015515" iyz="6.5283E-11" izz="0.0041284"/>
    </inertial>
  </link>

  <joint name="left_wheel_joint" type="continuous">
    <parent link="base_link"/>
    <child link="left_wheel"/>
    <origin xyz="-0.015294 0.18886 -0.079763" rpy="-1.57 0 0"/>
    <axis xyz="0 0 1"/>
  </joint>

  <link name="left_wheel">
    <visual>
      <origin xyz="0 0 0" rpy="1.57 0 0"/>
      <geometry>
        <mesh filename="package://autobot/meshes/left_wheel.STL"/>
      </geometry>
      <material name="light_black"/> <!-- Changed to a defined material -->
    </visual>

    <collision>
      <origin xyz="0 0 0" rpy="1.57 0 0"/>
      <geometry>
        <mesh filename="package://autobot/meshes/left_wheel.STL"/>
      </geometry>
    </collision>

    <inertial>
      <origin xyz="-1.534E-06 -0.0035 -8.1363E-05" rpy="1.57 0 0"/>
      <mass value="0.10364"/>
      <inertia ixx="8.7625E-05" ixy="1.3327E-18" ixz="2.4026E-21" iyy="0.00016817" iyz="-2.6053E-19" izz="8.7625E-05"/>
    </inertial>
  </link>

  <joint name="right_wheel_joint" type="continuous">
    <parent link="base_link"/>
    <child link="right_wheel"/>
    <origin xyz="-0.016418 -0.18164 -0.079762" rpy="1.57 0 0"/>
    <axis xyz="0 0 -1"/>
  </joint>

  <link name="right_wheel">
    <visual>
      <origin xyz="0 0 0" rpy="1.57 0 0"/>
      <geometry>
        <mesh filename="package://autobot/meshes/right_wheel.STL"/>
      </geometry>
      <material name="light_black"/> <!-- Changed to a defined material -->
    </visual>

    <collision>
      <origin xyz="0 0 0" rpy="1.57 0 0"/>
      <geometry>
        <mesh filename="package://autobot/meshes/right_wheel.STL"/>
      </geometry>
    </collision>

    <inertial>
      <origin xyz="-1.1077E-07 0.0035 -8.1377E-05" rpy="1.57 0 0"/>
      <mass value="0.10364"/>
      <inertia ixx="8.7625E-05" ixy="1.349E-18" ixz="-1.8576E-20" iyy="0.00016817" iyz="-3.0937E-19" izz="8.7625E-05"/>
    </inertial>
  </link>

  <joint name="castor_wheels_joint" type="revolute">
    <parent link="base_link"/>
    <child link="castor_wheels"/>
    <origin xyz="0.17607 0.003608 -0.079343" rpy="0 0 0"/>
    <axis xyz="0 1 0"/>
    <limit effort="10" velocity="5"/>
    <dynamics damping="0.0" friction="0.0"/>

    <gazebo>
      <mu1>0.001</mu1>
      <mu2>0.001</mu2>
    </gazebo>
  </joint>

  <link name="castor_wheels">
    <inertial>
      <origin xyz="5.5511E-17 7.6762E-16 4.1633E-17" rpy="0 0 0"/>
      <mass value="0.1"/>
      <inertia ixx="9.1441E-05" ixy="1.239E-18" ixz="3.9667E-21" iyy="0.00018051" iyz="-1.6989E-19" izz="9.1441E-05"/>
    </inertial>
    <visual>
      <origin xyz="0 0 0" rpy="0 0 0"/>
      <geometry>
        <mesh filename="package://autobot/meshes/castor_wheels.STL"/>
      </geometry>
      <material name="">
        <color rgba="0.79216 0.81961 0.93333 1"/>
      </material>
    </visual>
    <collision>
      <origin xyz="0 0 0" rpy="0 0 0"/>
      <geometry>
        <mesh filename="package://autobot/meshes/castor_wheels.STL"/>
      </geometry>
    </collision>
  </link>

  <joint name="lidar_joint" type="fixed">
    <parent link="base_link"/>
    <child link="lidar"/>
    <origin xyz="0.063868 0.006608 0.070657" rpy="0 0 0"/>
  </joint>

  <link name="lidar">
    <visual>
      <origin xyz="0 0 -0.02" rpy="0 0 0"/>
      <geometry>
        <mesh filename="package://autobot/meshes/lidar.STL"/>
      </geometry>
      <material name="light_black"/>
    </visual>
    <collision>
      <origin xyz="0 0 0" rpy="0 0 0"/>
      <geometry>
        <mesh filename="package://autobot/meshes/lidar.STL"/>
      </geometry>
    </collision>
    <inertial>
      <origin xyz="0 0 0" rpy="0 0 0"/>
      <mass value="0.008"/>
      <inertia ixx="2.7301E-06" ixy="0.0" ixz="0.0" iyy="2.7301E-06" iyz="0.0" izz="4.4311E-07"/>
    </inertial>
  </link>

  <!-- Camera joint -->
  <!-- Uncomment and correct if needed -->
  <!--
  <joint name="camera_joint" type="fixed">
    <parent link="base_link"/>
    <child link="camera_link"/>
    <origin xyz="0 0 0.2" rpy="0 0 0"/>
  </joint>

  <link name="camera_link">
    <visual>
      <origin xyz="0 0 0.2" rpy="0 0 0"/>
      <geometry>
        <mesh filename="package://autobot/meshes/camera.STL"/>
      </geometry>
      <material name="light_black"/>
    </visual>
  </link>
  -->

</robot>
